<?xml version="1.0"?>

<robot name="mobileRoboticArm" xmlns:xacro="http://ros.org/wiki/xacro">

	<!--Materials Start-->
	<material name="black">
		<color rgba="0.0 0.0 0.0 1.0"/>
	</material>

	<material name="white">
		<color rgba="1.0 1.0 1.0 1.0"/>
	</material>

	<material name="red">
		<color rgba="0.8 0.0 0.0 1.0"/>
	</material>

	<material name="blue">
		<color rgba="0.0 0.0 0.8 1.0"/>
	</material>

	<material name="green">
		<color rgba="0.0 0.8 0.0 1.0"/>
	</material>

	<material name="grey">
		<color rgba="0.5 0.5 0.5 1.0"/>
	</material>

	<material name="orange">
		<color rgba="${255/255} ${108/255} ${10/255} 1.0"/>
	</material>

	<material name="brown">
		<color rgba="${222/255} ${207/255} ${195/255} 1.0"/>
	</material>
	<!--Materials End-->

	<!--MACROS START-->

	<!--Inertial Macro-->
	<xacro:macro name="default_inertial" params="mass">
		<inertial>
			<origin xyz="0 0 0" rpy="0 0 0"/>
			<mass value="10"/>
			<inertia ixx="1" ixy="0" ixz="0" iyy="1" iyz="0" izz="1"/>
		</inertial>
	</xacro:macro>
	<!--Inertial Macro-->

	<!--Arm Link Macro-->
	<xacro:macro name="arm_link" params="suffix parent reflect height color mesh_path mass joint_type lower_limit upper_limit">
		<link name="arm_link_${suffix}">
			<visual>
				<origin xyz="0 0 0" rpy="0 0 0"/>
				<geometry>
					<!--mesh filename="package://innomech/meshes/linked_mx_64t.stl" scale="0.01 0.01 0.01"/-->
					<mesh filename="${mesh_path}" scale="0.01 0.01 0.01"/>
				</geometry>
				<material name="${color}"/>
			</visual>

			<collision>
				<origin xyz="0 0 0" rpy="0 0 0"/>
				<geometry>
					<mesh filename="${mesh_path}" scale="0.01 0.01 0.01"/>
				</geometry>
			</collision>
			<xacro:default_inertial mass="${mass}"/>
		</link>	

		<!-- Joint-->
		<joint name="${parent}_arm_link_${suffix}_joint" type="${joint_type}">
			<parent link="${parent}"/>
			<child link="arm_link_${suffix}"/>
			<origin xyz="0 0 ${height}" rpy="0 0 0"/>
			<axis xyz="0 1 0"/>
			<limit velocity="4.8" effort="1" lower="${lower_limit}" upper="${upper_limit}" />
		</joint>
	</xacro:macro>
	<!--Arm Link Macro-->

	<!--Wheel Macro-->
	<xacro:macro name="wheel_link" params="suffix parent reflect height color mesh_path mass joint_type">
		<link name="wheel_${suffix}">
			<visual>
				<origin xyz="0 0 0" rpy="${-reflect*pi/2} 0 0"/>
				<geometry>
					<!--mesh filename="package://innomech/meshes/wheel_left_link2.stl" scale="0.01 0.01 0.01"/-->
					<mesh filename="${mesh_path}" scale="0.01 0.01 0.01"/>
				</geometry>
				<material name="${color}"/>
			</visual>

			<collision>
				<origin xyz="0 0.14 0" rpy="${-reflect*pi/2} 0 0"/>
				<geometry>
					<mesh filename="${mesh_path}" scale="0.01 0.01 0.01"/>
				</geometry>
			</collision>
			<xacro:default_inertial mass="${mass}"/>
		</link>	

		<!-- Joint-->
		<joint name="wheel_${suffix}_joint" type="${joint_type}">
			<parent link="${parent}"/>
			<child link="wheel_${suffix}"/>
			<origin xyz="0 ${reflect*0.14} 0" rpy="0 0 0"/>
			<axis xyz="0 1 0"/>
			<limit velocity="4.8" effort="1" lower="${-pi}" upper="${pi}" />
		</joint>
	</xacro:macro>
	<!--Wheel Macro-->

	<!--MACROS END-->


	<!-- World -->
	<link name="world">
	</link>

	<!-- World fixed joint-->
	<joint name="world_fixed" type="fixed">
		<origin xyz="0 0 0" rpy="0 0 0"/>
		<parent link="world"/>
		<child link="base_link"/>
	</joint>

	<!-- Base_link -->
	<link name="base_link">
		<visual>
			<origin xyz="0 0 0" rpy="0 0 0"/>
			<geometry>
				<mesh filename="package://innomech/meshes/base_link2.stl" scale="0.01 0.01 0.01"/>
			</geometry>
			<material name="white"/>
		</visual>

		<collision>
			<origin xyz="0 0 0" rpy="0 0 0"/>
			<geometry>
				<mesh filename="package://innomech/meshes/base_link2.stl" scale="0.01 0.01 0.01"/>
			</geometry>
		</collision>

		<xacro:default_inertial mass="10"/>
	</link>

	<!-- Left Wheel -->
	<xacro:wheel_link suffix="left" parent="base_link" reflect="1" height="1" color="black" mesh_path="package://innomech/meshes/wheel_left_link2.stl" mass="5" joint_type="revolute"/>
	<!-- Left Wheel -->

	<!-- Right Wheel -->
	<xacro:wheel_link suffix="right" parent="base_link" reflect="-1" height="1" color="black" mesh_path="package://innomech/meshes/wheel_left_link2.stl" mass="5" joint_type="revolute"/>
	<!-- Right Wheel -->


	<!-- Joint BaseToArm1 -->
	<joint name="baseToMotor1" type="revolute">
		<parent link="base_link"/>
		<child link="motor1"/>
		<origin xyz="0 0 0.25" rpy="0 0 0"/>
		<axis xyz="0 0 1"/>
		<limit velocity="4.8" effort="1" lower="${-pi*0.9}" upper="${pi*0.9}" />
	</joint>

	<!-- Motor1 -->
	<link name="motor1">
		<visual>
			<origin xyz="0 0 0" rpy="0 0 0"/>
			<geometry>
				<mesh filename="package://innomech/meshes/mx-64t2.stl" scale="0.01 0.01 0.01"/>
			</geometry>
			<material name="blue"/>
		</visual>

		<collision>
			<origin xyz="0 0 0" rpy="0 0 0"/>
			<geometry>
				<mesh filename="package://innomech/meshes/mx-64t2.stl" scale="0.01 0.01 0.01"/>
			</geometry>
		</collision>
	</link>			

	<!-- Link1 -->
	<xacro:arm_link suffix="1" parent="motor1" reflect="1" height="0.0" color="red" mesh_path="package://innomech/meshes/linked_mx_64t.stl" mass="10" joint_type="revolute" lower_limit="${-pi/4}" upper_limit="${pi/4}"/>
	<!-- Link1 -->

	<!-- Link2 -->
	<xacro:arm_link suffix="2" parent="arm_link_1" reflect="1" height="0.12" color="green" mesh_path="package://innomech/meshes/linked_mx_64t.stl" mass="10" joint_type="revolute" lower_limit="${-pi/4}" upper_limit="${pi/4}"/>
	<!-- Link2 -->

	<!-- Link3 -->
	<xacro:arm_link suffix="3" parent="arm_link_2" reflect="1" height="0.12" color="grey" mesh_path="package://innomech/meshes/linked_mx_64t.stl" mass="10" joint_type="revolute" lower_limit="${-pi/4}" upper_limit="${pi/4}"/>
	<!-- Link3 -->

</robot>