<?xml version="1.0"?>

<robot xmlns:xacro="http://www.ros.org/wiki/xacro" name="robot">

 <!-- include materials /-->
 <xacro:include filename="$(find robot_description)/model/materials.xacro" />

  <!-- World -->
  <!--<link name="world_link">
  </link>-->

  <!-- World fixed joint-->
  <!--<joint name="world_fixed_joint" type="fixed">
    <origin xyz="0 0 0" rpy="0 0 0"/>
    <parent link="world_link"/>
    <child link="base_link"/>
  </joint>-->
  


  <link name="base_link">
    
    <inertial>
        <mass value="1.488"/>
        <origin xyz="0 0 0.068"  />
        <inertia ixx="0.0047" ixy="0.0" ixz="0.0047" iyy="0." iyz="0.0" izz="0.053"/>
    </inertial> 

    <collision>
      <origin xyz="0 0 0.008" rpy="0 0 0"/>
      <geometry>
        <mesh filename="package://robot_description/new_meshes/base.stl" scale="0.001 0.001 0.001"/>
        <!--box size="0.146 0.146 0.129"/ -->
      </geometry>
    </collision>

    <visual>
      <origin xyz="0 0 0.008" rpy="0 0 0"/>
      <geometry>
        <mesh filename="package://robot_description/new_meshes/base.stl" scale="0.001 0.001 0.001"/>
        <!--box size="0.146 0.146 0.129"/ -->
      </geometry>
      <material name="white"/>
    </visual>

  </link>

    <!-- Joint wheel_left_joint -->
  <joint name="wheel_left_joint" type="continuous">
    <parent link="base_link"/>
    <child link="wheel_left_link"/>
    <origin xyz="-0.06 -0.073 0.055" rpy="0 0 0"/>
    <axis xyz="0 1 0"/>
  </joint>

  <!-- wheel_left_link -->
  <link name="wheel_left_link">
    <visual>
      <origin xyz="0 0 0" rpy="0 0 0"/>
      <geometry>
        <mesh filename="package://robot_description/new_meshes/wheel_left.stl" scale="0.01 0.01 0.01"/>
      </geometry>
      <material name="brown"/>
    </visual>

    <collision>
      <origin xyz="0 0 0" rpy="0 0 0"/>
      <geometry>
        <cylinder length="0.030" radius="0.050"/>
      </geometry>
    </collision>

    <inertial>
      <origin xyz="0 0 0" />
      <mass value="2.8498940e-02" />
      <inertia ixx="1.1175580e-05" ixy="-4.2369783e-11" ixz="-5.9381719e-09"
               iyy="1.1192413e-05" iyz="-1.4400107e-11"
               izz="2.0712558e-05" />
      </inertial>
  </link>

  <!-- Joint wheel_right_joint -->
  <joint name="wheel_right_joint" type="continuous">
    <parent link="base_link"/>
    <child link="wheel_right_link"/>
    <origin xyz="-0.06 0.073 0.055" rpy="0 0 0"/>
    <axis xyz="0 1 0"/>
  </joint>

  <!-- wheel_right_link -->
  <link name="wheel_right_link">
    <visual>
      <origin xyz="0 0 0" rpy="0 0 0"/>
      <geometry>
        <mesh filename="package://robot_description/new_meshes/wheel_right.stl" scale="0.01 0.01 0.01"/>
      </geometry>
      <material name="brown"/>
    </visual>

    <collision>
      <origin xyz="0 0 0" rpy="0 0 0"/>
      <geometry>
        <cylinder length="0.030" radius="0.050"/>
      </geometry>
    </collision>

    <inertial>
      <origin xyz="0 0 0" />
      <mass value="2.8498940e-02" />
      <inertia ixx="1.1175580e-05" ixy="-4.2369783e-11" ixz="-5.9381719e-09"
               iyy="1.1192413e-05" iyz="-1.4400107e-11"
               izz="2.0712558e-05" />
      </inertial>
  </link>

  <!-- Joint BaseToJoint1 -->
	<joint name="link1_fixed_joint" type="fixed">
		<parent link="base_link"/>
		<child link="link_1"/>
		<origin xyz="0 0 0.137" rpy="0 0 0"/>
		<!-- <axis xyz="0 0 1"/> -->
		<!-- <limit velocity="4.8" effort="1" lower="${-pi*0.9}" upper="${pi*0.9}" /> -->
	</joint>

	<!-- link_1 -->
  <link name="link_1">

     <inertial>
        <mass value="0.165"/>
        <origin xyz="0 0.024 0.0205"  />
        <inertia ixx="0.00007" ixy="0.0" ixz="0.0" iyy="0.00005" iyz="0.0" izz="0.0001"/>
    </inertial>

		<visual>
			<origin xyz="0 0 0.0" rpy="0 0 0"/>
			<geometry>
				<mesh filename="package://robot_description/new_meshes/mx-64tobase.stl" scale="0.01 0.01 0.01"/>
			</geometry>
			<material name="blue"/>
		</visual>

		<collision>
			<origin xyz="0 0 0.0" rpy="0 0 0"/>
			<geometry>
				<mesh filename="package://robot_description/new_meshes/mx-64tobase.stl" scale="0.01 0.01 0.01"/>
			</geometry>
		</collision>
	</link>	

  <!-- joint1 -->
  <joint name="joint1" type="revolute">
    <parent link="link_1"/>
    <child link="link_2"/>
    <origin xyz="0 0.0 0.044" rpy="0 0 0"/>
    <axis xyz="0 0 1"/>
    <limit velocity="0.8" effort="1" lower="-3.14" upper="3.14" />
  </joint>

  <!-- link_2 -->
  <link name="link_2">

    <inertial>
        <mass value="0.165"/>
        <origin xyz="0 0.0 -0.0175"  />
        <inertia ixx="0.00007" ixy="0.0" ixz="0.0" iyy="0.0001" iyz="0.0" izz="0.00005"/>
    </inertial>

    <visual>
      <origin xyz="0 0 0.0" rpy="0 0 0"/>
      <geometry>
        <mesh filename="package://robot_description/new_meshes/mx-64second.stl" scale="0.01 0.01 0.01"/>
      </geometry>
      <material name="red"/>
    </visual>

    <collision>
      <origin xyz="0 0 0.0" rpy="0 0 0"/>
      <geometry>
        <mesh filename="package://robot_description/new_meshes/mx-64second.stl" scale="0.01 0.01 0.01"/>
      </geometry>
    </collision>
  </link> 

  <!-- joint2 -->
  <joint name="joint2" type="revolute">
    <parent link="link_2"/>
    <child link="link_3"/>
    <origin xyz="0 0.0 0.058" rpy="0 0 0"/>
    <axis xyz="0 1 0"/>
    <limit velocity="4.8" effort="1" lower="-2.2" upper="2.2" />
  </joint>

  <!-- link_3 -->
  <link name="link_3">

    <inertial>
        <mass value="0.215"/>
        <origin xyz="0 0.0 0.100"  />
        <inertia ixx="0.00004" ixy="0.0" ixz="0.0" iyy="0.00004" iyz="0.0" izz="0.00007"/>
    </inertial>

    <visual>
      <origin xyz="0 0 0" rpy="0 0 0"/>
      <geometry>
        <mesh filename="package://robot_description/meshes/linked_mx_64t.stl" scale="0.01 0.01 0.01"/>
      </geometry>
      <material name="green"/>
    </visual>

    <collision>
      <origin xyz="0 0 0" rpy="0 0 0"/>
      <geometry>
        <mesh filename="package://robot_description/meshes/linked_mx_64t.stl" scale="0.01 0.01 0.01"/>
      </geometry>
    </collision>
  </link> 

  <!-- joint3 -->
  <joint name="joint3" type="revolute">
    <parent link="link_3"/>
    <child link="link_4"/>
    <origin xyz="0 0.0 0.12" rpy="0 0 0"/>
    <axis xyz="0 1 0"/>
    <limit velocity="4.8" effort="1" lower="-2.1" upper="2.1" />
  </joint>

  <!-- link_4 -->
  <link name="link_4">

    <inertial>
        <mass value="0.215"/>
        <origin xyz="0 0.0 0.100"  />
        <inertia ixx="0.00004" ixy="0.0" ixz="0.0" iyy="0.00004" iyz="0.0" izz="0.00007"/>
    </inertial>

    <visual>
      <origin xyz="0 0 0" rpy="0 0 0"/>
      <geometry>
        <mesh filename="package://robot_description/meshes/linked_mx_64t.stl" scale="0.01 0.01 0.01"/>
      </geometry>
      <material name="orange"/>
    </visual>

    <collision>
      <origin xyz="0 0 0" rpy="0 0 0"/>
      <geometry>
        <mesh filename="package://robot_description/meshes/linked_mx_64t.stl" scale="0.01 0.01 0.01"/>
      </geometry>
    </collision>
  </link> 

  <!-- joint4 -->
  <joint name="joint4" type="revolute">
    <parent link="link_4"/>
    <child link="link_5"/>
    <origin xyz="0 0 0.12" rpy="0 0 0"/>
    <axis xyz="0 1 0"/>
    <limit effort="4.8" lower="-2.1" upper="2.1" velocity="10"/>
  </joint>

  <!-- link5 -->
  <link name="link_5">
    <collision>
      <origin xyz="0 0 0.0" rpy="0 0 0"/>
      <geometry>
        <mesh filename="package://robot_description/new_meshes/mx-64togripper2.stl" scale="0.001 0.001 0.001"/>
      </geometry>
    </collision>

    <visual>
      <origin xyz="0 0 0.0" rpy="0 0 0"/>
      <geometry>
        <mesh filename="package://robot_description/new_meshes/mx-64togripper2.stl" scale="0.001 0.001 0.001"/>
      </geometry>
      <material name="white"/>
    </visual>

    <inertial>
      <origin xyz="0 0 0.0" rpy="0 0 0"/>
      <mass value="0.050"/>
      <inertia ixx="1.0" ixy="0.0" ixz="0.0" iyy="1.0" iyz="0.0" izz="1.0"/>
    </inertial>
  </link>
  
  <!-- joint5 -->
  <joint name="joint5" type="prismatic">
    <parent link="link_5"/>
    <child link="link_gripper_left"/>
    <origin xyz="0 -0.0245 0.069" rpy="0 0 0"/>
    <axis xyz="0 1 0"/>
    <!--<limit velocity="4.8" effort="1" lower="-0.0245" upper="-0.0455" />-->
    <limit velocity="4.8" effort="1" lower="0.0" upper="-0.021" />
  </joint>
  
  <!-- GripperLeft -->
  <link name="link_gripper_left">
    <collision>
      <origin xyz="0 0 0.0" rpy="0 0 0"/>
      <geometry>
        <mesh filename="package://robot_description/new_meshes/gripper_l.stl" scale="0.001 0.001 0.001"/>
      </geometry>
    </collision>

    <visual>
      <origin xyz="0 0 0.0" rpy="0 0 0"/>
      <geometry>
         <mesh filename="package://robot_description/new_meshes/gripper_l.stl" scale="0.001 0.001 0.001"/>
      </geometry>
      <material name="white"/>
    </visual>

    <inertial>
      <origin xyz="0 0 0.0" rpy="0 0 0"/>
      <mass value="0.050"/>
      <inertia ixx="1.0" ixy="0.0" ixz="0.0" iyy="1.0" iyz="0.0" izz="1.0"/>
    </inertial>
  </link>


  <!-- joint5_mimic -->
  <joint name="joint5_mimic" type="prismatic">
    <parent link="link_5"/>
    <child link="link_gripper_right"/>
    <origin xyz="0 0.0245 0.069" rpy="0 0 0"/>
    <axis xyz="0 1 0"/>
    <!--<limit velocity="4.8" effort="1" lower="0.0245" upper="0.0455" />-->
    <limit velocity="4.8" effort="1" lower="0.0" upper="0.021" />
    <mimic joint="joint5" multiplier="-1" />
  </joint>
  
  <!-- GripperRight -->
  <link name="link_gripper_right">
    <collision>
      <origin xyz="0 0 0.0" rpy="0 0 0"/>
      <geometry>
        <mesh filename="package://robot_description/new_meshes/gripper_r.stl" scale="0.001 0.001 0.001"/>
      </geometry>
    </collision>

    <visual>
      <origin xyz="0 0 0.0" rpy="0 0 0"/>
      <geometry>
         <mesh filename="package://robot_description/new_meshes/gripper_r.stl" scale="0.001 0.001 0.001"/>
      </geometry>
      <material name="white"/>
    </visual>

    <inertial>
      <origin xyz="0 0 0.0" rpy="0 0 0"/>
      <mass value="0.050"/>
      <inertia ixx="1.0" ixy="0.0" ixz="0.0" iyy="1.0" iyz="0.0" izz="1.0"/>
    </inertial>
  </link>

  <!-- end effector joint -->
  <joint name="end_effector_joint" type="fixed">
    <origin xyz="0 0.0 0.074" rpy="0 0 0"/>
    <parent link="link_5"/>
    <child link="end_effector_link"/>
  </joint>

  <!-- end effector link -->
  <link name="end_effector_link">
    <visual>
      <origin xyz="0 0 0" rpy="0 0 0"/>
      <geometry>
        <box size="0.01 0.01 0.01" />
      </geometry>
      <material name="red"/>
     </visual>

    <inertial>
      <origin xyz="0.0 0.0 0.0" rpy="0 0 0"/>
      <mass value="0.001"/>
      <inertia ixx="1.0e-06" ixy="0.0" ixz="0.0" iyy="1.0e-06" iyz="0.0" izz="1.0e-06" />
    </inertial>
  </link>

   
   </robot>
